Traceback (most recent call last):
  File "/opt/conda/envs/omini_env/lib/python3.10/site-packages/urllib3/connectionpool.py", line 787, in urlopen
    response = self._make_request(
  File "/opt/conda/envs/omini_env/lib/python3.10/site-packages/urllib3/connectionpool.py", line 488, in _make_request
    raise new_e
  File "/opt/conda/envs/omini_env/lib/python3.10/site-packages/urllib3/connectionpool.py", line 464, in _make_request
    self._validate_conn(conn)
  File "/opt/conda/envs/omini_env/lib/python3.10/site-packages/urllib3/connectionpool.py", line 1093, in _validate_conn
    conn.connect()
  File "/opt/conda/envs/omini_env/lib/python3.10/site-packages/urllib3/connection.py", line 704, in connect
    self.sock = sock = self._new_conn()
  File "/opt/conda/envs/omini_env/lib/python3.10/site-packages/urllib3/connection.py", line 213, in _new_conn
    raise NewConnectionError(
urllib3.exceptions.NewConnectionError: <urllib3.connection.HTTPSConnection object at 0x14d2c802e980>: Failed to establish a new connection: [Errno 101] Network is unreachable

The above exception was the direct cause of the following exception:

Traceback (most recent call last):
  File "/opt/conda/envs/omini_env/lib/python3.10/site-packages/requests/adapters.py", line 667, in send
    resp = conn.urlopen(
  File "/opt/conda/envs/omini_env/lib/python3.10/site-packages/urllib3/connectionpool.py", line 841, in urlopen
    retries = retries.increment(
  File "/opt/conda/envs/omini_env/lib/python3.10/site-packages/urllib3/util/retry.py", line 519, in increment
    raise MaxRetryError(_pool, url, reason) from reason  # type: ignore[arg-type]
urllib3.exceptions.MaxRetryError: HTTPSConnectionPool(host='openaipublic.blob.core.windows.net', port=443): Max retries exceeded with url: /encodings/cl100k_base.tiktoken (Caused by NewConnectionError('<urllib3.connection.HTTPSConnection object at 0x14d2c802e980>: Failed to establish a new connection: [Errno 101] Network is unreachable'))

During handling of the above exception, another exception occurred:

Traceback (most recent call last):
  File "/pfssmain/departments/hematologie_Onko_immuno/20250130_OLLAMA_HPC/omini/Omini_8/sdexllm.py", line 16, in <module>
    from utils.rag import retrieve_for_table
  File "/pfssmain/departments/hematologie_Onko_immuno/20250130_OLLAMA_HPC/omini/Omini_8/utils/rag.py", line 52, in <module>
    ENC               = tiktoken.encoding_for_model("text-embedding-3-large")
  File "/opt/conda/envs/omini_env/lib/python3.10/site-packages/tiktoken/model.py", line 110, in encoding_for_model
    return get_encoding(encoding_name_for_model(model_name))
  File "/opt/conda/envs/omini_env/lib/python3.10/site-packages/tiktoken/registry.py", line 86, in get_encoding
    enc = Encoding(**constructor())
  File "/opt/conda/envs/omini_env/lib/python3.10/site-packages/tiktoken_ext/openai_public.py", line 76, in cl100k_base
    mergeable_ranks = load_tiktoken_bpe(
  File "/opt/conda/envs/omini_env/lib/python3.10/site-packages/tiktoken/load.py", line 148, in load_tiktoken_bpe
    contents = read_file_cached(tiktoken_bpe_file, expected_hash)
  File "/opt/conda/envs/omini_env/lib/python3.10/site-packages/tiktoken/load.py", line 63, in read_file_cached
    contents = read_file(blobpath)
  File "/opt/conda/envs/omini_env/lib/python3.10/site-packages/tiktoken/load.py", line 22, in read_file
    resp = requests.get(blobpath)
  File "/opt/conda/envs/omini_env/lib/python3.10/site-packages/requests/api.py", line 73, in get
    return request("get", url, params=params, **kwargs)
  File "/opt/conda/envs/omini_env/lib/python3.10/site-packages/requests/api.py", line 59, in request
    return session.request(method=method, url=url, **kwargs)
  File "/opt/conda/envs/omini_env/lib/python3.10/site-packages/requests/sessions.py", line 589, in request
    resp = self.send(prep, **send_kwargs)
  File "/opt/conda/envs/omini_env/lib/python3.10/site-packages/requests/sessions.py", line 703, in send
    r = adapter.send(request, **kwargs)
  File "/opt/conda/envs/omini_env/lib/python3.10/site-packages/requests/adapters.py", line 700, in send
    raise ConnectionError(e, request=request)
requests.exceptions.ConnectionError: HTTPSConnectionPool(host='openaipublic.blob.core.windows.net', port=443): Max retries exceeded with url: /encodings/cl100k_base.tiktoken (Caused by NewConnectionError('<urllib3.connection.HTTPSConnection object at 0x14d2c802e980>: Failed to establish a new connection: [Errno 101] Network is unreachable'))
Python-Skript beendet (Exit Code: 1). Beende ollama (PID: 1583493)...
[vanjan02@hpc01-gpunode011 omini]$
